Workbook

Sheet Dashboard
B1: SALES INTELLIGENCE DASHBOARD
B2: ="Sales transactions | "&TEXT(Analysis!$B$12,"dd mmm yyyy")&" to "&TEXT(Analysis!$B$13,"dd mmm yyyy")&" | "&Analysis!$B$36&" transactions | Last refreshed "&TEXT(NOW(),"dd mmm yyyy hh:mm:ss") -> Sales transactions | 01 Jan 2023 to 01 Jan 2024 | 1000 transactions | Last refreshed 24 Oct 2026 15:53:40
B4: KEY PERFORMANCE INDICATORS
B5: TOTAL SALES | E5: TRANSACTIONS | H5: UNITS SOLD | K5: AVERAGE SALE | N5: AVG DISCOUNT | Q5: NET MARGIN %
B6: =Analysis!$B$35 -> 5019265.2 | E6: =Analysis!$B$36 -> 1000 | H6: =Analysis!$B$37 -> 25355 | K6: =Analysis!$B$38 -> 5019.2652 | N6: =Analysis!$B$40 -> 0.15239 | Q6: =Analysis!$B$46 -> -0.069629528
B7: =IF(H51>=0,"▲ ","▼ ")&TEXT(ABS(H51),"0.0%")&" vs target" -> ▼ 8.7% vs target | E7: =IF(H52>=0,"▲ ","▼ ")&TEXT(ABS(H52),"0.0%")&" vs target" -> ▼ 9.1% vs target | H7: =TEXT(Analysis!$B$37/Analysis!$B$36,"0.0")&" units per sale" -> 25.4 units per sale | K7: =IF(H53>=0,"▲ ","▼ ")&TEXT(ABS(H53),"0.0%")&" vs target" -> ▲ 0.4% vs target | N7: ="Break-even: "&TEXT(Analysis!$B$49,"0.0%") -> Break-even: 9.2% | Q7: =IF(H54>=0,"▲ ","▼ ")&TEXT(ABS(H54)*100,"0.0")&" pts vs target" -> ▼ 12.0 pts vs target
B9: INTERACTIVE FILTERS: choose from the dropdowns, the charts below update instantly
B10: REGION | E10: PRODUCT CATEGORY | H10: SALES REP | K10: SALES CHANNEL | N10: FROM DATE | Q10: TO DATE
B11: All | E11: All | H11: All | K11: All | N11: 44927 | Q11: 45322
B13: SELECTED SALES | E13: TRANSACTIONS | H13: UNITS | K13: AVG DISCOUNT | N13: NET MARGIN % | Q13: VIEW
B14: =Calc!B66 -> 5019265.2 | E14: =Calc!B67 -> 1000 | H14: =Calc!B68 -> 25355 | K14: =Calc!B69 -> 0.15239 | N14: =Calc!B70 -> -0.069629528 | Q14: =Calc!B72 -> Full dataset (no filters)
B16: TRENDS & MIX (respond to the filters above)
B17: Monthly Sales Trend | K17: Sales by Region
B33: Sales by Product Category | H33: Sales by Sales Rep | N33: Net Margin % by Discount Band
B49: PERFORMANCE VS TARGET | TOP 10 REGION-REP COMBINATIONS
B50: KPI | D50: Actual | F50: Target | H50: Variance | I50: Status | K50: Rank | L50: Region-Rep | O50: Sales | Q50: Share of sales
B51: Total Sales | D51: =Analysis!$B$35 -> 5019265.2 | F51: 5500000 | H51: =D51/F51-1 -> -0.087406322 | I51: =IF(H51>=0,"On target",IF(H51>=-0.1,"Watch","Behind")) -> Watch | K51: =Performance!L4 -> 1 | L51: =Performance!M4 -> South-David | O51: =Performance!N4 -> 311416.99 | Q51: =Performance!O4 -> 0.062044338
B52: Transactions | D52: =Analysis!$B$36 -> 1000 | F52: 1100 | H52: =D52/F52-1 -> -0.090909091 | I52: =IF(H52>=0,"On target",IF(H52>=-0.1,"Watch","Behind")) -> Watch | K52: =Performance!L5 -> 2 | L52: =Performance!M5 -> East-Bob | O52: =Performance!N5 -> 309876.11 | Q52: =Performance!O5 -> 0.061737345
B53: Average Sale | D53: =Analysis!$B$38 -> 5019.2652 | F53: 5000 | H53: =D53/F53-1 -> 0.003853046 | I53: =IF(H53>=0,"On target",IF(H53>=-0.1,"Watch","Behind")) -> On target | K53: =Performance!L6 -> 3 | L53: =Performance!M6 -> North-Eve | O53: =Performance!N6 -> 304172.2 | Q53: =Performance!O6 -> 0.060600942
B54: Net Margin % | D54: =Analysis!$B$46 -> -0.069629528 | F54: 0.05 | H54: =D54-F54 -> -0.11962953 | I54: =IF(H54>=0,"On target",IF(H54>=-0.1,"Watch","Behind")) -> Behind | K54: =Performance!L7 -> 4 | L54: =Performance!M7 -> North-Charlie | O54: =Performance!N7 -> 299789.01 | Q54: =Performance!O7 -> 0.059727669
B55: Loss-making share (lower is better) | D55: =Analysis!$B$51 -> 0.604 | F55: 0.25 | H55: =F55-D55 -> -0.354 | I55: =IF(H55>=0,"On target",IF(H55>=-0.1,"Watch","Behind")) -> Behind | K55: =Performance!L8 -> 5 | L55: =Performance!M8 -> West-Bob | O55: =Performance!N8 -> 286449.28 | Q55: =Performance!O8 -> 0.057069963
B56: Yellow targets are placeholder assumptions, not dataset values. | K56: =Performance!L9 -> 6 | L56: =Performance!M9 -> East-David | O56: =Performance!N9 -> 284613.51 | Q56: =Performance!O9 -> 0.056704218
B57: Region-Rep tiers | K57: =Performance!L10 -> 7 | L57: =Performance!M10 -> North-David | O57: =Performance!N10 -> 282539.27 | Q57: =Performance!O10 -> 0.056290962
B58: High-Value | D58: =COUNTIF(Performance!$I$4:$I$23,"High-Value") -> 4 | F58: =SUMIF(Performance!$I$4:$I$23,"High-Value",Performance!$D$4:$D$23) -> 1225254.3 | H58: =F58/Analysis!$B$35 -> 0.24411029 | K58: =Performance!L11 -> 8 | L58: =Performance!M11 -> West-David | O58: =Performance!N11 -> 263167.59 | Q58: =Performance!O11 -> 0.052431497
B59: Mid | D59: =COUNTIF(Performance!$I$4:$I$23,"Mid") -> 6 | F59: =SUMIF(Performance!$I$4:$I$23,"Mid",Performance!$D$4:$D$23) -> 1628759.6 | H59: =F59/Analysis!$B$35 -> 0.32450159 | K59: =Performance!L12 -> 9 | L59: =Performance!M12 -> East-Alice | O59: =Performance!N12 -> 260789.47 | Q59: =Performance!O12 -> 0.051957699
B60: Low | D60: =COUNTIF(Performance!$I$4:$I$23,"Low") -> 10 | F60: =SUMIF(Performance!$I$4:$I$23,"Low",Performance!$D$4:$D$23) -> 2165251.4 | H60: =F60/Analysis!$B$35 -> 0.43138812 | K60: =Performance!L13 -> 10 | L60: =Performance!M13 -> South-Bob | O60: =Performance!N13 -> 251200.43 | Q60: =Performance!O13 -> 0.050047252
B62: PIVOT TABLES, PIVOT CHARTS & SLICERS: the four slicers on the right filter every PivotTable and pivot chart (click an item; Ctrl-click for several; the funnel icon clears). Refresh All after data changes.
B63: Sales by Region | E63: Sales by Category | H63: Sales by Rep | K63: Sales by Month | N63: Sales by Payment
B64: Filter | E64: Filter | H64: Filter | K64: Filter | N64: Filter
B65: Product_Category | C65: - all - | E65: Region | F65: - all - | H65: Region | I65: - all - | K65: Region | L65: - all - | N65: Region | O65: - all -
B66: Sales_Channel | C66: - all - | E66: Sales_Channel | F66: - all - | H66: Product_Category | I66: - all - | K66: Product_Category | L66: - all - | N66: Product_Category | O66: - all -
B68: Region | C68: Sales ($) | E68: Product_Category | F68: Sales ($) | H68: Sales_Rep | I68: Sales ($) | K68: Year_Month | L68: Sales ($) | N68: Payment_Method | O68: Sales ($)
B69: East | C69: 1259792.9 | E69: Clothing | F69: 1313474.4 | H69: Alice | I69: 965541.77 | K69: 2023-01 | L69: 476092.36 | N69: Bank Transfer | O69: 1717363.2
B70: North | C70: 1369612.5 | E70: Electronics | F70: 1243499.6 | H70: Bob | I70: 1080990.6 | K70: 2023-02 | L70: 368919.36 | N70: Cash | O70: 1544338.5
B71: South | C71: 1154250.9 | E71: Food | F71: 1201773.5 | H71: Charlie | I71: 860811.48 | K71: 2023-03 | L71: 402638.77 | N71: Credit Card | O71: 1757563.5
B72: West | C72: 1235608.9 | E72: Furniture | F72: 1260517.7 | H72: David | I72: 1141737.4 | K72: 2023-04 | L72: 438992.61 | N72: Grand Total | O72: 5019265.2
B73: Grand Total | C73: 5019265.2 | E73: Grand Total | F73: 5019265.2 | H73: Eve | I73: 970183.99 | K73: 2023-05 | L73: 389078.76
H74: Grand Total | I74: 5019265.2 | K74: 2023-06 | L74: 418458.34
K75: 2023-07 | L75: 374242.88
K76: 2023-08 | L76: 443171.28
...

Sheet Report
B1: Final Report: Insights & Storytelling
B2: Every sentence below is a formula, so it updates with the data. Targets and scenario inputs are placeholder assumptions.
B4: 1. The big picture
B5: ="Sales total "&TEXT(Analysis!$B$35,"$#,##0")&" from "&TEXT(Analysis!$B$36,"#,##0")&" transactions ("&TEXT(Analysis!$B$37,"#,##0")&" units) between "&TEXT(Analysis!$B$12,"d mmm yyyy")&" and "&TEXT(Analysis!$B$13,"d mmm yyyy")&". The average sale is "&TEXT(Analysis!$B$38,"$#,##0")&" and the median "&TEXT(Analysis!$B$39,"$#,##0")&"; individual sales range widely (coefficient of variation "&TEXT(Analysis!$B$202,"0%")&"), with "&Analysis!$B$203&" outliers beyond two standard deviations." -> Sales total $50,19,265 from 1,000 transactions (25,355 units) between 1 Jan 2023 and 1 Jan 2024. The average sale is $5,019 and the median $5,019; individual sales range widely (coefficient of variation 57%), with 0 outliers beyond two standard deviations.
B7: 2. Where and what
B8: ="Region: "&Analysis!$B$61&" leads with "&TEXT(MAX(Analysis!$C$56:$C$59),"$#,##0")&" and "&Analysis!$B$62&" trails with "&TEXT(MIN(Analysis!$C$56:$C$59),"$#,##0")&" (a "&TEXT(MAX(Analysis!$C$56:$C$59)/MIN(Analysis!$C$56:$C$59)-1,"0%")&" gap). Category: "&Analysis!$B$71&" leads ("&TEXT(MAX(Analysis!$C$66:$C$69),"$#,##0")&") and "&Analysis!$B$72&" is lowest ("&TEXT(MIN(Analysis!$C$66:$C$69),"$#,##0")&"). Sales are spread fairly evenly, so no single region or category carries the business." -> Region: North leads with $13,69,613 and South trails with $11,54,251 (a 19% gap). Category: Clothing leads ($13,13,474) and Food is lowest ($12,01,774). Sales are spread fairly evenly, so no single region or category carries the business.
B10: 3. People
B11: ="Top sales rep: "&Analysis!$B$82&" ("&TEXT(MAX(Analysis!$C$76:$C$80),"$#,##0")&"); lowest: "&Analysis!$B$83&" ("&TEXT(MIN(Analysis!$C$76:$C$80),"$#,##0")&"). The best Region-Rep combination is "&Performance!M4&" at "&TEXT(Performance!N4,"$#,##0")&"; "&COUNTIF(Performance!$Q$4:$Q$23,"A")&" of 20 combinations produce the first 80% of sales (Pareto class A)." -> Top sales rep: David ($11,41,737); lowest: Charlie ($8,60,811). The best Region-Rep combination is South-David at $3,11,417; 14 of 20 combinations produce the first 80% of sales (Pareto class A).
B13: 4. Channel and customers
B14: ="Retail sells "&TEXT(Analysis!C88,"$#,##0")&" versus Online "&TEXT(Analysis!C87,"$#,##0")&"; returning customers account for "&TEXT(Analysis!D96,"0.0%")&" of sales and new customers "&TEXT(Analysis!D95,"0.0%")&". The differences are small, so channel and customer type are not performance levers on their own. Most-used payment method: "&Analysis!$B$107&"." -> Retail sells $25,60,431 versus Online $24,58,834; returning customers account for 50.1% of sales and new customers 49.9%. The differences are small, so channel and customer type are not performance levers on their own. Most-used payment method: Credit Card.
B16: 5. Time patterns
B17: ="Best full month: "&INDEX(Analysis!B167:B178,MATCH(MAX(Analysis!E167:E178),Analysis!E167:E178,0))&"; weakest: "&INDEX(Analysis!B167:B178,MATCH(MIN(Analysis!E167:E178),Analysis!E167:E178,0))&". Best weekday: "&Analysis!$B$138&"; weakest: "&Analysis!$B$139&". Strongest quarter: "&Analysis!$B$149&". The monthly trend slope is "&TEXT('Regression Output'!$B$21,"$#,##0")&" per month with Significance F "&TEXT('Regression Output'!$F$14,"0.000")&": "&IF('Regression Output'!$F$14<0.05,"a significant trend.","no statistically significant trend, sales are flat with random swings.") -> Best full month: Jan-23; weakest: Sep-23. Best weekday: Thursday; weakest: Saturday. Strongest quarter: 2023-Q4. The monthly trend slope is $474 per month with Significance F 0.894: no statistically significant trend, sales are flat with random swings.
B19: 6. The discount story (key insight)
B20: ="The weighted average discount is "&TEXT(Analysis!$B$48,"0.0%")&" against a break-even level of "&TEXT(Analysis!$B$49,"0.0%")&" (the discount at which net margin on a list-price basis is zero). Net margin is "&TEXT(Analysis!$B$46,"0.0%")&" and "&TEXT(Analysis!$B$51,"0%")&" of sales ("&Analysis!$B$50&") lose money after discount. By band, net margin is "&TEXT(Analysis!H112,"0.0%")&" at 0-9% discount, "&TEXT(Analysis!H113,"0.0%")&" at 10-19% and "&TEXT(Analysis!H114,"0.0%")&" at 20%+. Discount is not buying larger sales: correlation of discount with Sales_Amount is only "&TEXT(Analysis!$B$204,"0.00")&"." -> The weighted average discount is 15.1% against a break-even level of 9.2% (the discount at which net margin on a list-price basis is zero). Net margin is -7.0% and 60% of sales (604) lose money after discount. By band, net margin is 4.5% at 0-9% discount, -5.8% at 10-19% and -20.8% at 20%+. Discount is not buying larger sales: correlation of discount with Sales_Amount is only 0.02.
B22: 7. Regression findings
B23: ='Regression Output'!A90&" "&'Regression Output'!A91&" "&'Regression Output'!A92 -> A) Trend: sales move $474 per month (R² 0.002, Significance F 0.894): NOT significant, so monthly sales are flat apart from random swings. B) Drivers: Quantity, Discount and Unit_Price together explain only 0.2% of Sales_Amount (Significance F 0.483): none of these fields predicts the size of a sale. C) Discount vs margin: every +1 percentage point of discount changes net margin by -1.14% (R² 0.223, p-value 0.0000): statistically significant.
B25: 8. Scenarios and Goal Seek
B26: ="Projected net margin: Base "&TEXT(Analysis!C222,"0.0%")&"; Discount discipline "&TEXT(Analysis!D222,"0.0%")&" (sales "&TEXT(Analysis!D219/Analysis!C219-1,"+0.0%;-0.0%")&"); Growth push "&TEXT(Analysis!E222,"0.0%")&"; Price rise "&TEXT(Analysis!F222,"0.0%")&". Goal Seek: to reach a "&TEXT(Analysis!$B$224,"0%")&" net margin the weighted discount must fall to "&TEXT(Analysis!$B$225,"0.0%")&", a change of "&TEXT(Analysis!$B$226*100,"0.0")&" percentage points." -> Projected net margin: Base -7.0%; Discount discipline -1.0% (sales +2.7%); Growth push -10.9%; Price rise -1.9%. Goal Seek: to reach a 5% net margin the weighted discount must fall to 4.4%, a change of -10.7 percentage points.
B28: 9. Data-quality findings
B29: ="(1) Sales_Amount does not reconcile to Quantity x Unit_Price (correlation "&TEXT(CORREL('Raw Data'!$O$2:$O$1001,'Raw Data'!$E$2:$E$1001),"0.00")&"), so margins use the list-price basis. (2) "&'Product IDs'!$P$12&" of "&COUNT('Product IDs'!A4:A103)&" Product_IDs appear under all four categories and only "&'Product IDs'!$P$9&" under one, so Product_ID is not a reliable product key. (3) There is no customer identifier, so customer-level analysis is not possible. (4) January 2024 contains a single day. (5) Floating-point noise in Unit_Price was rounded to 2 decimals." -> (1) Sales_Amount does not reconcile to Quantity x Unit_Price (correlation -0.03), so margins use the list-price basis. (2) 71 of 100 Product_IDs appear under all four categories and only 0 under one, so Product_ID is not a reliable product key. (3) There is no customer identifier, so customer-level analysis is not possible. (4) January 2024 contains a single day. (5) Floating-point noise in Unit_Price was rounded to 2 decimals.
B31: 10. Recommendations
B32: ="(1) Cap discounts: aim for a weighted discount near "&TEXT(Analysis!$B$225,"0%")&" and review every deal above 20% ("&COUNTIF('Raw Data'!$U$2:$U$1001,"20%+")&" sales). (2) Share the practices of "&Analysis!$B$82&" and coach "&Analysis!$B$83&". (3) Lift "&Analysis!$B$62&" with targeted campaigns. (4) Fix master data: unique product keys, a customer ID and reconciled sales amounts. (5) Track net margin by discount band monthly on the Dashboard." -> (1) Cap discounts: aim for a weighted discount near 4% and review every deal above 20% (380 sales). (2) Share the practices of David and coach Charlie. (3) Lift South with targeted campaigns. (4) Fix master data: unique product keys, a customer ID and reconciled sales amounts. (5) Track net margin by discount band monthly on the Dashboard.

Sheet Raw Data
A1: Product_ID | B1: Sale_Date | C1: Sales_Rep | D1: Region | E1: Sales_Amount | F1: Quantity_Sold | G1: Product_Category | H1: Unit_Cost | I1: Unit_Price | J1: Customer_Type | K1: Discount | L1: Payment_Method | M1: Sales_Channel | N1: Region_and_Sales_Rep | O1: List_Value | P1: Net_List_Value | Q1: COGS | R1: Net_Margin | S1: Net_Margin_Pct | T1: Loss_Flag | U1: Discount_Band | V1: Sales_Size | W1: Year_Month | X1: Month_End | Y1: Year_Quarter | Z1: Weekday | AA1: Weekday_No | AB1: Week_No | AC1: Day_Type | AD1: Days_Since_Sale | AE1: Age_Months | AF1: Rep_Code | AG1: Order_Code | AH1: Filter_Seq | AI1: X1_Quantity | AJ1: X2_Discount | AK1: X3_Unit_Price | AL1: Sales_Rank
A2: 1052 | B2: 44960 | C2: Bob | D2: North | E2: 5053.97 | F2: 18 | G2: Furniture | H2: 152.75 | I2: 267.22 | J2: Returning | K2: 0.09 | L2: Cash | M2: Online | N2: North-Bob | O2: =ROUND(F2*I2,2) -> 4809.96 | P2: =ROUND(F2*I2*(1-K2),2) -> 4377.06 | Q2: =ROUND(F2*H2,2) -> 2749.5 | R2: =P2-Q2 -> 1627.56 | S2: =IF(P2=0,0,R2/P2) -> 0.37183863 | T2: =IF(R2<0,"Loss","OK") -> OK | U2: =IF(K2<0.1,"0-9%",IF(K2<0.2,"10-19%","20%+")) -> 0-9% | V2: =IF(E2>=Analysis!$B$4,"High",IF(E2>=Analysis!$B$5,"Mid","Low")) -> Mid | W2: =TEXT(B2,"yyyy-mm") -> 2023-02 | X2: =EOMONTH(B2,0) -> 44985 | Y2: =YEAR(B2)&"-Q"&ROUNDUP(MONTH(B2)/3,0) -> 2023-Q1 | Z2: =TEXT(B2,"ddd") -> Fri | AA2: =WEEKDAY(B2,2) -> 5 | AB2: =WEEKNUM(B2,2) -> 6 | AC2: =IF(AA2>5,"Weekend","Weekday") -> Weekday | AD2: =TODAY()-B2 -> 1359 | AE2: =DATEDIF(B2,TODAY(),"M") -> 44 | AF2: =UPPER(LEFT(C2,3)) -> BOB | AG2: =UPPER(LEFT(D2,1))&UPPER(LEFT(M2,1))&"-"&TEXT(B2,"yymmdd")&"-"&TEXT(ROW()-1,"0000") -> NO-230203-0001 | AH2: =IF(AND(OR(Filter!$B$4="All",D2=Filter!$B$4),OR(Filter!$B$5="All",M2=Filter!$B$5),E2>=Filter!$B$6),MAX(AH$1:AH1)+1,"") | AI2: =F2 -> 18 | AJ2: =K2 -> 0.09 | AK2: =I2 -> 267.22 | AL2: =RANK(E2,$E$2:$E$1001,0)+COUNTIF($E$2:E2,E2)-1 -> 496
A3: 1093 | B3: 45037 | C3: Bob | D3: West | E3: 4384.02 | F3: 17 | G3: Furniture | H3: 3816.39 | I3: 4209.44 | J3: Returning | K3: 0.11 | L3: Cash | M3: Retail | N3: West-Bob | O3: =ROUND(F3*I3,2) -> 71560.48 | P3: =ROUND(F3*I3*(1-K3),2) -> 63688.83 | Q3: =ROUND(F3*H3,2) -> 64878.63 | R3: =P3-Q3 -> -1189.8 | S3: =IF(P3=0,0,R3/P3) -> -0.018681455 | T3: =IF(R3<0,"Loss","OK") -> Loss | U3: =IF(K3<0.1,"0-9%",IF(K3<0.2,"10-19%","20%+")) -> 10-19% | V3: =IF(E3>=Analysis!$B$4,"High",IF(E3>=Analysis!$B$5,"Mid","Low")) -> Mid | W3: =TEXT(B3,"yyyy-mm") -> 2023-04 | X3: =EOMONTH(B3,0) -> 45046 | Y3: =YEAR(B3)&"-Q"&ROUNDUP(MONTH(B3)/3,0) -> 2023-Q2 | Z3: =TEXT(B3,"ddd") -> Fri | AA3: =WEEKDAY(B3,2) -> 5 | AB3: =WEEKNUM(B3,2) -> 17 | AC3: =IF(AA3>5,"Weekend","Weekday") -> Weekday | AD3: =TODAY()-B3 -> 1282 | AE3: =DATEDIF(B3,TODAY(),"M") -> 42 | AF3: =UPPER(LEFT(C3,3)) -> BOB | AG3: =UPPER(LEFT(D3,1))&UPPER(LEFT(M3,1))&"-"&TEXT(B3,"yymmdd")&"-"&TEXT(ROW()-1,"0000") -> WR-230421-0002 | AH3: =IF(AND(OR(Filter!$B$4="All",D3=Filter!$B$4),OR(Filter!$B$5="All",M3=Filter!$B$5),E3>=Filter!$B$6),MAX(AH$1:AH2)+1,"") | AI3: =F3 -> 17 | AJ3: =K3 -> 0.11 | AK3: =I3 -> 4209.44 | AL3: =RANK(E3,$E$2:$E$1001,0)+COUNTIF($E$2:E3,E3)-1 -> 562
A4: 1015 | B4: 45190 | C4: David | D4: South | E4: 4631.23 | F4: 30 | G4: Food | H4: 261.56 | I4: 371.4 | J4: Returning | K4: 0.2 | L4: Bank Transfer | M4: Retail | N4: South-David | O4: =ROUND(F4*I4,2) -> 11142 | P4: =ROUND(F4*I4*(1-K4),2) -> 8913.6 | Q4: =ROUND(F4*H4,2) -> 7846.8 | R4: =P4-Q4 -> 1066.8 | S4: =IF(P4=0,0,R4/P4) -> 0.11968228 | T4: =IF(R4<0,"Loss","OK") -> OK | U4: =IF(K4<0.1,"0-9%",IF(K4<0.2,"10-19%","20%+")) -> 20%+ | V4: =IF(E4>=Analysis!$B$4,"High",IF(E4>=Analysis!$B$5,"Mid","Low")) -> Mid | W4: =TEXT(B4,"yyyy-mm") -> 2023-09 | X4: =EOMONTH(B4,0) -> 45199 | Y4: =YEAR(B4)&"-Q"&ROUNDUP(MONTH(B4)/3,0) -> 2023-Q3 | Z4: =TEXT(B4,"ddd") -> Thu | AA4: =WEEKDAY(B4,2) -> 4 | AB4: =WEEKNUM(B4,2) -> 39 | AC4: =IF(AA4>5,"Weekend","Weekday") -> Weekday | AD4: =TODAY()-B4 -> 1129 | AE4: =DATEDIF(B4,TODAY(),"M") -> 37 | AF4: =UPPER(LEFT(C4,3)) -> DAV | AG4: =UPPER(LEFT(D4,1))&UPPER(LEFT(M4,1))&"-"&TEXT(B4,"yymmdd")&"-"&TEXT(ROW()-1,"0000") -> SR-230921-0003 | AH4: =IF(AND(OR(Filter!$B$4="All",D4=Filter!$B$4),OR(Filter!$B$5="All",M4=Filter!$B$5),E4>=Filter!$B$6),MAX(AH$1:AH3)+1,"") | AI4: =F4 -> 30 | AJ4: =K4 -> 0.2 | AK4: =I4 -> 371.4 | AL4: =RANK(E4,$E$2:$E$1001,0)+COUNTIF($E$2:E4,E4)-1 -> 539
A5: 1072 | B5: 45162 | C5: Bob | D5: South | E5: 2167.94 | F5: 39 | G5: Clothing | H5: 4330.03 | I5: 4467.75 | J5: New | K5: 0.02 | L5: Credit Card | M5: Retail | N5: South-Bob | O5: =ROUND(F5*I5,2) -> 174242.25 | P5: =ROUND(F5*I5*(1-K5),2) -> 170757.41 | Q5: =ROUND(F5*H5,2) -> 168871.17 | R5: =P5-Q5 -> 1886.24 | S5: =IF(P5=0,0,R5/P5) -> 0.011046314 | T5: =IF(R5<0,"Loss","OK") -> OK | U5: =IF(K5<0.1,"0-9%",IF(K5<0.2,"10-19%","20%+")) -> 0-9% | V5: =IF(E5>=Analysis!$B$4,"High",IF(E5>=Analysis!$B$5,"Mid","Low")) -> Low | W5: =TEXT(B5,"yyyy-mm") -> 2023-08 | X5: =EOMONTH(B5,0) -> 45169 | Y5: =YEAR(B5)&"-Q"&ROUNDUP(MONTH(B5)/3,0) -> 2023-Q3 | Z5: =TEXT(B5,"ddd") -> Thu | AA5: =WEEKDAY(B5,2) -> 4 | AB5: =WEEKNUM(B5,2) -> 35 | AC5: =IF(AA5>5,"Weekend","Weekday") -> Weekday | AD5: =TODAY()-B5 -> 1157 | AE5: =DATEDIF(B5,TODAY(),"M") -> 38 | AF5: =UPPER(LEFT(C5,3)) -> BOB | AG5: =UPPER(LEFT(D5,1))&UPPER(LEFT(M5,1))&"-"&TEXT(B5,"yymmdd")&"-"&TEXT(ROW()-1,"0000") -> SR-230824-0004 | AH5: =IF(AND(OR(Filter!$B$4="All",D5=Filter!$B$4),OR(Filter!$B$5="All",M5=Filter!$B$5),E5>=Filter!$B$6),MAX(AH$1:AH4)+1,"") | AI5: =F5 -> 39 | AJ5: =K5 -> 0.02 | AK5: =I5 -> 4467.75 | AL5: =RANK(E5,$E$2:$E$1001,0)+COUNTIF($E$2:E5,E5)-1 -> 796
A6: 1061 | B6: 45009 | C6: Charlie | D6: East | E6: 3750.2 | F6: 13 | G6: Electronics | H6: 637.37 | I6: 692.71 | J6: New | K6: 0.08 | L6: Credit Card | M6: Online | N6: East-Charlie | O6: =ROUND(F6*I6,2) -> 9005.23 | P6: =ROUND(F6*I6*(1-K6),2) -> 8284.81 | Q6: =ROUND(F6*H6,2) -> 8285.81 | R6: =P6-Q6 -> -1 | S6: =IF(P6=0,0,R6/P6) -> -0.00012070283 | T6: =IF(R6<0,"Loss","OK") -> Loss | U6: =IF(K6<0.1,"0-9%",IF(K6<0.2,"10-19%","20%+")) -> 0-9% | V6: =IF(E6>=Analysis!$B$4,"High",IF(E6>=Analysis!$B$5,"Mid","Low")) -> Mid | W6: =TEXT(B6,"yyyy-mm") -> 2023-03 | X6: =EOMONTH(B6,0) -> 45016 | Y6: =YEAR(B6)&"-Q"&ROUNDUP(MONTH(B6)/3,0) -> 2023-Q1 | Z6: =TEXT(B6,"ddd") -> Fri | AA6: =WEEKDAY(B6,2) -> 5 | AB6: =WEEKNUM(B6,2) -> 13 | AC6: =IF(AA6>5,"Weekend","Weekday") -> Weekday | AD6: =TODAY()-B6 -> 1310 | AE6: =DATEDIF(B6,TODAY(),"M") -> 43 | AF6: =UPPER(LEFT(C6,3)) -> CHA | AG6: =UPPER(LEFT(D6,1))&UPPER(LEFT(M6,1))&"-"&TEXT(B6,"yymmdd")&"-"&TEXT(ROW()-1,"0000") -> EO-230324-0005 | AH6: =IF(AND(OR(Filter!$B$4="All",D6=Filter!$B$4),OR(Filter!$B$5="All",M6=Filter!$B$5),E6>=Filter!$B$6),MAX(AH$1:AH5)+1,"") | AI6: =F6 -> 13 | AJ6: =K6 -> 0.08 | AK6: =I6 -> 692.71 | AL6: =RANK(E6,$E$2:$E$1001,0)+COUNTIF($E$2:E6,E6)-1 -> 625
A7: 1021 | B7: 44968 | C7: Charlie | D7: West | E7: 3761.15 | F7: 32 | G7: Food | H7: 900.79 | I7: 1106.51 | J7: New | K7: 0.21 | L7: Cash | M7: Online | N7: West-Charlie | O7: =ROUND(F7*I7,2) -> 35408.32 | P7: =ROUND(F7*I7*(1-K7),2) -> 27972.57 | Q7: =ROUND(F7*H7,2) -> 28825.28 | R7: =P7-Q7 -> -852.71 | S7: =IF(P7=0,0,R7/P7) -> -0.030483792 | T7: =IF(R7<0,"Loss","OK") -> Loss | U7: =IF(K7<0.1,"0-9%",IF(K7<0.2,"10-19%","20%+")) -> 20%+ | V7: =IF(E7>=Analysis!$B$4,"High",IF(E7>=Analysis!$B$5,"Mid","Low")) -> Mid | W7: =TEXT(B7,"yyyy-mm") -> 2023-02 | X7: =EOMONTH(B7,0) -> 44985 | Y7: =YEAR(B7)&"-Q"&ROUNDUP(MONTH(B7)/3,0) -> 2023-Q1 | Z7: =TEXT(B7,"ddd") -> Sat | AA7: =WEEKDAY(B7,2) -> 6 | AB7: =WEEKNUM(B7,2) -> 7 | AC7: =IF(AA7>5,"Weekend","Weekday") -> Weekend | AD7: =TODAY()-B7 -> 1351 | AE7: =DATEDIF(B7,TODAY(),"M") -> 44 | AF7: =UPPER(LEFT(C7,3)) -> CHA | AG7: =UPPER(LEFT(D7,1))&UPPER(LEFT(M7,1))&"-"&TEXT(B7,"yymmdd")&"-"&TEXT(ROW()-1,"0000") -> WO-230211-0006 | AH7: =IF(AND(OR(Filter!$B$4="All",D7=Filter!$B$4),OR(Filter!$B$5="All",M7=Filter!$B$5),E7>=Filter!$B$6),MAX(AH$1:AH6)+1,"") | AI7: =F7 -> 32 | AJ7: =K7 -> 0.21 | AK7: =I7 -> 1106.51 | AL7: =RANK(E7,$E$2:$E$1001,0)+COUNTIF($E$2:E7,E7)-1 -> 622
A8: 1083 | B8: 45027 | C8: Bob | D8: West | E8: 618.31 | F8: 29 | G8: Furniture | H8: 2408.81 | I8: 2624.09 | J8: Returning | K8: 0.14 | L8: Cash | M8: Online | N8: West-Bob | O8: =ROUND(F8*I8,2) -> 76098.61 | P8: =ROUND(F8*I8*(1-K8),2) -> 65444.8 | Q8: =ROUND(F8*H8,2) -> 69855.49 | R8: =P8-Q8 -> -4410.69 | S8: =IF(P8=0,0,R8/P8) -> -0.067395576 | T8: =IF(R8<0,"Loss","OK") -> Loss | U8: =IF(K8<0.1,"0-9%",IF(K8<0.2,"10-19%","20%+")) -> 10-19% | V8: =IF(E8>=Analysis!$B$4,"High",IF(E8>=Analysis!$B$5,"Mid","Low")) -> Low | W8: =TEXT(B8,"yyyy-mm") -> 2023-04 | X8: =EOMONTH(B8,0) -> 45046 | Y8: =YEAR(B8)&"-Q"&ROUNDUP(MONTH(B8)/3,0) -> 2023-Q2 | Z8: =TEXT(B8,"ddd") -> Tue | AA8: =WEEKDAY(B8,2) -> 2 | AB8: =WEEKNUM(B8,2) -> 16 | AC8: =IF(AA8>5,"Weekend","Weekday") -> Weekday | AD8: =TODAY()-B8 -> 1292 | AE8: =DATEDIF(B8,TODAY(),"M") -> 42 | AF8: =UPPER(LEFT(C8,3)) -> BOB | AG8: =UPPER(LEFT(D8,1))&UPPER(LEFT(M8,1))&"-"&TEXT(B8,"yymmdd")&"-"&TEXT(ROW()-1,"0000") -> WO-230411-0007 | AH8: =IF(AND(OR(Filter!$B$4="All",D8=Filter!$B$4),OR(Filter!$B$5="All",M8=Filter!$B$5),E8>=Filter!$B$6),MAX(AH$1:AH7)+1,"") | AI8: =F8 -> 29 | AJ8: =K8 -> 0.14 | AK8: =I8 -> 2624.09 | AL8: =RANK(E8,$E$2:$E$1001,0)+COUNTIF($E$2:E8,E8)-1 -> 950
A9: 1087 | B9: 44932 | C9: Eve | D9: South | E9: 7698.92 | F9: 46 | G9: Furniture | H9: 3702.51 | I9: 3964.65 | J9: New | K9: 0.12 | L9: Bank Transfer | M9: Online | N9: South-Eve | O9: =ROUND(F9*I9,2) -> 182373.9 | P9: =ROUND(F9*I9*(1-K9),2) -> 160489.03 | Q9: =ROUND(F9*H9,2) -> 170315.46 | R9: =P9-Q9 -> -9826.43 | S9: =IF(P9=0,0,R9/P9) -> -0.061228048 | T9: =IF(R9<0,"Loss","OK") -> Loss | U9: =IF(K9<0.1,"0-9%",IF(K9<0.2,"10-19%","20%+")) -> 10-19% | V9: =IF(E9>=Analysis!$B$4,"High",IF(E9>=Analysis!$B$5,"Mid","Low")) -> High | W9: =TEXT(B9,"yyyy-mm") -> 2023-01 | X9: =EOMONTH(B9,0) -> 44957 | Y9: =YEAR(B9)&"-Q"&ROUNDUP(MONTH(B9)/3,0) -> 2023-Q1 | Z9: =TEXT(B9,"ddd") -> Fri | AA9: =WEEKDAY(B9,2) -> 5 | AB9: =WEEKNUM(B9,2) -> 2 | AC9: =IF(AA9>5,"Weekend","Weekday") -> Weekday | AD9: =TODAY()-B9 -> 1387 | AE9: =DATEDIF(B9,TODAY(),"M") -> 45 | AF9: =UPPER(LEFT(C9,3)) -> EVE | AG9: =UPPER(LEFT(D9,1))&UPPER(LEFT(M9,1))&"-"&TEXT(B9,"yymmdd")&"-"&TEXT(ROW()-1,"0000") -> SO-230106-0008 | AH9: =IF(AND(OR(Filter!$B$4="All",D9=Filter!$B$4),OR(Filter!$B$5="All",M9=Filter!$B$5),E9>=Filter!$B$6),MAX(AH$1:AH8)+1,"") | AI9: =F9 -> 46 | AJ9: =K9 -> 0.12 | AK9: =I9 -> 3964.65 | AL9: =RANK(E9,$E$2:$E$1001,0)+COUNTIF($E$2:E9,E9)-1 -> 227
A10: 1075 | B10: 45106 | C10: David | D10: South | E10: 4223.39 | F10: 30 | G10: Furniture | H10: 738.06 | I10: 1095.45 | J10: New | K10: 0.05 | L10: Bank Transfer | M10: Online | N10: South-David | O10: =ROUND(F10*I10,2) -> 32863.5 | P10: =ROUND(F10*I10*(1-K10),2) -> 31220.33 | Q10: =ROUND(F10*H10,2) -> 22141.8 | R10: =P10-Q10 -> 9078.53 | S10: =IF(P10=0,0,R10/P10) -> 0.29078905 | T10: =IF(R10<0,"Loss","OK") -> OK | U10: =IF(K10<0.1,"0-9%",IF(K10<0.2,"10-19%","20%+")) -> 0-9% | V10: =IF(E10>=Analysis!$B$4,"High",IF(E10>=Analysis!$B$5,"Mid","Low")) -> Mid | W10: =TEXT(B10,"yyyy-mm") -> 2023-06 | X10: =EOMONTH(B10,0) -> 45107 | Y10: =YEAR(B10)&"-Q"&ROUNDUP(MONTH(B10)/3,0) -> 2023-Q2 | Z10: =TEXT(B10,"ddd") -> Thu | AA10: =WEEKDAY(B10,2) -> 4 | AB10: =WEEKNUM(B10,2) -> 27 | AC10: =IF(AA10>5,"Weekend","Weekday") -> Weekday | AD10: =TODAY()-B10 -> 1213 | AE10: =DATEDIF(B10,TODAY(),"M") -> 39 | AF10: =UPPER(LEFT(C10,3)) -> DAV | AG10: =UPPER(LEFT(D10,1))&UPPER(LEFT(M10,1))&"-"&TEXT(B10,"yymmdd")&"-"&TEXT(ROW()-1,"0000") -> SO-230629-0009 | AH10: =IF(AND(OR(Filter!$B$4="All",D10=Filter!$B$4),OR(Filter!$B$5="All",M10=Filter!$B$5),E10>=Filter!$B$6),MAX(AH$1:AH9)+1,"") | AI10: =F10 -> 30 | AJ10: =K10 -> 0.05 | AK10: =I10 -> 1095.45 | AL10: =RANK(E10,$E$2:$E$1001,0)+COUNTIF($E$2:E10,E10)-1 -> 578
A11: 1075 | B11: 45208 | C11: Charlie | D11: West | E11: 8239.58 | F11: 18 | G11: Clothing | H11: 2228.35 | I11: 2682.34 | J11: New | K11: 0.13 | L11: Bank Transfer | M11: Online | N11: West-Charlie | O11: =ROUND(F11*I11,2) -> 48282.12 | P11: =ROUND(F11*I11*(1-K11),2) -> 42005.44 | Q11: =ROUND(F11*H11,2) -> 40110.3 | R11: =P11-Q11 -> 1895.14 | S11: =IF(P11=0,0,R11/P11) -> 0.045116537 | T11: =IF(R11<0,"Loss","OK") -> OK | U11: =IF(K11<0.1,"0-9%",IF(K11<0.2,"10-19%","20%+")) -> 10-19% | V11: =IF(E11>=Analysis!$B$4,"High",IF(E11>=Analysis!$B$5,"Mid","Low")) -> High | W11: =TEXT(B11,"yyyy-mm") -> 2023-10 | X11: =EOMONTH(B11,0) -> 45230 | Y11: =YEAR(B11)&"-Q"&ROUNDUP(MONTH(B11)/3,0) -> 2023-Q4 | Z11: =TEXT(B11,"ddd") -> Mon | AA11: =WEEKDAY(B11,2) -> 1 | AB11: =WEEKNUM(B11,2) -> 42 | AC11: =IF(AA11>5,"Weekend","Weekday") -> Weekday | AD11: =TODAY()-B11 -> 1111 | AE11: =DATEDIF(B11,TODAY(),"M") -> 36 | AF11: =UPPER(LEFT(C11,3)) -> CHA | AG11: =UPPER(LEFT(D11,1))&UPPER(LEFT(M11,1))&"-"&TEXT(B11,"yymmdd")&"-"&TEXT(ROW()-1,"0000") -> WO-231009-0010 | AH11: =IF(AND(OR(Filter!$B$4="All",D11=Filter!$B$4),OR(Filter!$B$5="All",M11=Filter!$B$5),E11>=Filter!$B$6),MAX(AH$1:AH10)+1,"") | AI11: =F11 -> 18 | AJ11: =K11 -> 0.13 | AK11: =I11 -> 2682.34 | AL11: =RANK(E11,$E$2:$E$1001,0)+COUNTIF($E$2:E11,E11)-1 -> 168
A12: 1088 | B12: 45246 | C12: Eve | D12: North | E12: 8518.45 | F12: 13 | G12: Furniture | H12: 2440.11 | I12: 2517.6 | J12: New | K12: 0.23 | L12: Bank Transfer | M12: Retail | N12: North-Eve | O12: =ROUND(F12*I12,2) -> 32728.8 | P12: =ROUND(F12*I12*(1-K12),2) -> 25201.18 | Q12: =ROUND(F12*H12,2) -> 31721.43 | R12: =P12-Q12 -> -6520.25 | S12: =IF(P12=0,0,R12/P12) -> -0.25872796 | T12: =IF(R12<0,"Loss","OK") -> Loss | U12: =IF(K12<0.1,"0-9%",IF(K12<0.2,"10-19%","20%+")) -> 20%+ | V12: =IF(E12>=Analysis!$B$4,"High",IF(E12>=Analysis!$B$5,"Mid","Low")) -> High | W12: =TEXT(B12,"yyyy-mm") -> 2023-11 | X12: =EOMONTH(B12,0) -> 45260 | Y12: =YEAR(B12)&"-Q"&ROUNDUP(MONTH(B12)/3,0) -> 2023-Q4 | Z12: =TEXT(B12,"ddd") -> Thu | AA12: =WEEKDAY(B12,2) -> 4 | AB12: =WEEKNUM(B12,2) -> 47 | AC12: =IF(AA12>5,"Weekend","Weekday") -> Weekday | AD12: =TODAY()-B12 -> 1073 | AE12: =DATEDIF(B12,TODAY(),"M") -> 35 | AF12: =UPPER(LEFT(C12,3)) -> EVE | AG12: =UPPER(LEFT(D12,1))&UPPER(LEFT(M12,1))&"-"&TEXT(B12,"yymmdd")&"-"&TEXT(ROW()-1,"0000") -> NR-231116-0011 | AH12: =IF(AND(OR(Filter!$B$4="All",D12=Filter!$B$4),OR(Filter!$B$5="All",M12=Filter!$B$5),E12>=Filter!$B$6),MAX(AH$1:AH11)+1,"") | AI12: =F12 -> 13 | AJ12: =K12 -> 0.23 | AK12: =I12 -> 2517.6 | AL12: =RANK(E12,$E$2:$E$1001,0)+COUNTIF($E$2:E12,E12)-1 -> 139
A13: 1100 | B13: 45152 | C13: Bob | D13: West | E13: 2198.74 | F13: 43 | G13: Food | H13: 1100.81 | I13: 1137.44 | J13: Returning | K13: 0.08 | L13: Bank Transfer | M13: Online | N13: West-Bob | O13: =ROUND(F13*I13,2) -> 48909.92 | P13: =ROUND(F13*I13*(1-K13),2) -> 44997.13 | Q13: =ROUND(F13*H13,2) -> 47334.83 | R13: =P13-Q13 -> -2337.7 | S13: =IF(P13=0,0,R13/P13) -> -0.051952202 | T13: =IF(R13<0,"Loss","OK") -> Loss | U13: =IF(K13<0.1,"0-9%",IF(K13<0.2,"10-19%","20%+")) -> 0-9% | V13: =IF(E13>=Analysis!$B$4,"High",IF(E13>=Analysis!$B$5,"Mid","Low")) -> Low | W13: =TEXT(B13,"yyyy-mm") -> 2023-08 | X13: =EOMONTH(B13,0) -> 45169 | Y13: =YEAR(B13)&"-Q"&ROUNDUP(MONTH(B13)/3,0) -> 2023-Q3 | Z13: =TEXT(B13,"ddd") -> Mon | AA13: =WEEKDAY(B13,2) -> 1 | AB13: =WEEKNUM(B13,2) -> 34 | AC13: =IF(AA13>5,"Weekend","Weekday") -> Weekday | AD13: =TODAY()-B13 -> 1167 | AE13: =DATEDIF(B13,TODAY(),"M") -> 38 | AF13: =UPPER(LEFT(C13,3)) -> BOB | AG13: =UPPER(LEFT(D13,1))&UPPER(LEFT(M13,1))&"-"&TEXT(B13,"yymmdd")&"-"&TEXT(ROW()-1,"0000") -> WO-230814-0012 | AH13: =IF(AND(OR(Filter!$B$4="All",D13=Filter!$B$4),OR(Filter!$B$5="All",M13=Filter!$B$5),E13>=Filter!$B$6),MAX(AH$1:AH12)+1,"") | AI13: =F13 -> 43 | AJ13: =K13 -> 0.08 | AK13: =I13 -> 1137.44 | AL13: =RANK(E13,$E$2:$E$1001,0)+COUNTIF($E$2:E13,E13)-1 -> 790
... A1001: 1086 | B1001: 45154 | C1001: Alice | D1001: East | E1001: 4923.93 | F1001: 48 | G1001: Food | H1001: 2632.58 | I1001: 2926.68 | J1001: Returning | K1001: 0.14 | L1001: Cash | M1001: Online | N1001: East-Alice | O1001: =ROUND(F1001*I1001,2) -> 140480.64 | P1001: =ROUND(F1001*I1001*(1-K1001),2) -> 120813.35 | Q1001: =ROUND(F1001*H1001,2) -> 126363.84 | R1001: =P1001-Q1001 -> -5550.49 | S1001: =IF(P1001=0,0,R1001/P1001) -> -0.045942688 | T1001: =IF(R1001<0,"Loss","OK") -> Loss | U1001: =IF(K1001<0.1,"0-9%",IF(K1001<0.2,"10-19%","20%+")) -> 10-19% | V1001: =IF(E1001>=Analysis!$B$4,"High",IF(E1001>=Analysis!$B$5,"Mid","Low")) -> Mid | W1001: =TEXT(B1001,"yyyy-mm") -> 2023-08 | X1001: =EOMONTH(B1001,0) -> 45169 | Y1001: =YEAR(B1001)&"-Q"&ROUNDUP(MONTH(B1001)/3,0) -> 2023-Q3 | Z1001: =TEXT(B1001,"ddd") -> Wed | AA1001: =WEEKDAY(B1001,2) -> 3 | AB1001: =WEEKNUM(B1001,2) -> 34 | AC1001: =IF(AA1001>5,"Weekend","Weekday") -> Weekday | AD1001: =TODAY()-B1001 -> 1165 | AE1001: =DATEDIF(B1001,TODAY(),"M") -> 38 | AF1001: =UPPER(LEFT(C1001,3)) -> ALI | AG1001: =UPPER(LEFT(D1001,1))&UPPER(LEFT(M1001,1))&"-"&TEXT(B1001,"yymmdd")&"-"&TEXT(ROW()-1,"0000") -> EO-230816-1000 | AH1001: =IF(AND(OR(Filter!$B$4="All",D1001=Filter!$B$4),OR(Filter!$B$5="All",M1001=Filter!$B$5),E1001>=Filter!$B$6),MAX(AH$1:AH1000)+1,"") | AI1001: =F1001 -> 48 | AJ1001: =K1001 -> 0.14 | AK1001: =I1001 -> 2926.68 | AL1001: =RANK(E1001,$E$2:$E$1001,0)+COUNTIF($E$2:E1001,E1001)-1 -> 509

Sheet Analysis
A1: Analysis
A3: 0. Parameters (drive the Sales_Size column in Raw Data)
A4: Large-sale threshold (75th percentile of Sales_Amount) | B4: =PERCENTILE('Raw Data'!$E$2:$E$1001,0.75) -> 7507.445
A5: Small-sale threshold (25th percentile of Sales_Amount) | B5: =PERCENTILE('Raw Data'!$E$2:$E$1001,0.25) -> 2550.2975
A7: 1. Date & Time Functions (TODAY, NOW, DATEDIF, EOMONTH, EDATE, NETWORKDAYS, WEEKNUM)
A8: Today | B8: =TODAY() -> 46319
A9: Now (date & time) | B9: =NOW() -> 46319.662
A10: End of current month | B10: =EOMONTH(TODAY(),0) -> 46326
A11: Start of current month | B11: =EOMONTH(TODAY(),-1)+1 -> 46296
A12: First sale | B12: =MIN('Raw Data'!$B$2:$B$1001) -> 44927
A13: Last sale | B13: =MAX('Raw Data'!$B$2:$B$1001) -> 45292
A14: Dataset span (months, DATEDIF) | B14: =DATEDIF(B12,B13,"M") -> 12
A15: Dataset span (days) | B15: =B13-B12 -> 365
A16: Working days in span (NETWORKDAYS) | B16: =NETWORKDAYS(B12,B13) -> 261
A17: Distinct selling days | B17: =SUMPRODUCT(1/COUNTIF('Raw Data'!$B$2:$B$1001,'Raw Data'!$B$2:$B$1001)) -> 340
A18: Average sales per selling day | B18: =B35/B17 -> 14762.545
A19: Days since last sale | B19: =TODAY()-B13 -> 1027
A20: Months since last sale (DATEDIF) | B20: =DATEDIF(B13,TODAY(),"M") -> 33
A21: Six months after first sale (EDATE) | B21: =EDATE(B12,6) -> 45108
A22: Weekday of last sale | B22: =TEXT(B13,"dddd") -> Monday
A23: ISO-style week of last sale (WEEKNUM) | B23: =WEEKNUM(B13,2) -> 1
A25: 2. Timestamp with NOW() + Iterative Calculation (circular on purpose; File > Options > Formulas > Enable iterative calculation)
A26: Entry (type here) | B26: Timestamp (freezes once typed) | C26: Elapsed since stamp
A27: Order batch 1 | B27: =IF(A27="","",IF(OR(B27="",B27=0),NOW(),B27)) -> 46319.426 | C27: =IF(B27="","",TEXT(NOW()-B27,"[h]:mm:ss")) -> 0:00:02
A28: Order batch 2 | B28: =IF(A28="","",IF(OR(B28="",B28=0),NOW(),B28)) -> 46319.426 | C28: =IF(B28="","",TEXT(NOW()-B28,"[h]:mm:ss")) -> 0:00:02
A29: Order batch 3 | B29: =IF(A29="","",IF(OR(B29="",B29=0),NOW(),B29)) -> 46319.426 | C29: =IF(B29="","",TEXT(NOW()-B29,"[h]:mm:ss")) -> 0:00:02
B30: =IF(A30="","",IF(OR(B30="",B30=0),NOW(),B30)) | C30: =IF(B30="","",TEXT(NOW()-B30,"[h]:mm:ss"))
B31: =IF(A31="","",IF(OR(B31="",B31=0),NOW(),B31)) | C31: =IF(B31="","",TEXT(NOW()-B31,"[h]:mm:ss"))
A32: Type anything in A30 or A31 and the timestamp appears and stays fixed (column C shows time elapsed since it was stamped).
A34: 3. Headline KPIs
A35: Total Sales | B35: =SUM('Raw Data'!$E$2:$E$1001) -> 5019265.2
A36: Transactions | B36: =COUNTA('Raw Data'!$E$2:$E$1001) -> 1000
A37: Units Sold | B37: =SUM('Raw Data'!$F$2:$F$1001) -> 25355
A38: Average Sale | B38: =AVERAGE('Raw Data'!$E$2:$E$1001) -> 5019.2652
A39: Median Sale | B39: =MEDIAN('Raw Data'!$E$2:$E$1001) -> 5019.3
A40: Average Discount | B40: =AVERAGE('Raw Data'!$K$2:$K$1001) -> 0.15239
A41: List Value (Qty x Unit_Price) | B41: =SUM('Raw Data'!$O$2:$O$1001) -> 70329941
A42: Net List Value (after discount) | B42: =SUM('Raw Data'!$P$2:$P$1001) -> 59686174
A43: Discount Given ($, list basis) | B43: =B41-B42 -> 10643767
A44: Cost of Goods (Qty x Unit_Cost) | B44: =SUM('Raw Data'!$Q$2:$Q$1001) -> 63842094
...

Sheet Performance
A1: Performance: GroupBy by Region-Rep, Pareto/ABC, Top Transactions
A2: No customer ID exists in this dataset, so the high-value GroupBy is built on Region-Rep combinations (matches Region_and_Sales_Rep). Tier: High-Value = 80th percentile or above, Mid = 50th to 80th, Low = below the median. | L2: Pareto / ABC ranking | S2: Top 10 Transactions (LARGE / INDEX-MATCH)
A3: Region-Rep | B3: Region | C3: Sales Rep | D3: Sales | E3: Transactions | F3: Avg Sale | G3: Net Margin % | H3: Rank | I3: Tier | J3: Share | L3: Rank | M3: Region-Rep | N3: Sales | O3: Share | P3: Cumulative | Q3: Class | S3: Rank | T3: Order_Code | U3: Date | V3: Rep | W3: Region | X3: Category | Y3: Channel | Z3: Sales_Amount
A4: East-Alice | B4: East | C4: Alice | D4: =SUMIFS('Raw Data'!$E$2:$E$1001,'Raw Data'!$N$2:$N$1001,A4) -> 260789.47 | E4: =COUNTIFS('Raw Data'!$N$2:$N$1001,A4) -> 52 | F4: =IF(E4=0,0,D4/E4) -> 5015.1821 | G4: =IFERROR(SUMIFS('Raw Data'!$R$2:$R$1001,'Raw Data'!$N$2:$N$1001,A4)/SUMIFS('Raw Data'!$P$2:$P$1001,'Raw Data'!$N$2:$N$1001,A4),0) -> -0.067180386 | H4: =RANK(D4,$D$4:$D$23,0)+COUNTIF($D$4:D4,D4)-1 -> 9 | I4: =IF(D4>=PERCENTILE($D$4:$D$23,0.8),"High-Value",IF(D4>=PERCENTILE($D$4:$D$23,0.5),"Mid","Low")) -> Mid | J4: =D4/SUM($D$4:$D$23) -> 0.051957699 | L4: 1 | M4: =INDEX($A$4:$A$23,MATCH(L4,$H$4:$H$23,0)) -> South-David | N4: =INDEX($D$4:$D$23,MATCH(L4,$H$4:$H$23,0)) -> 311416.99 | O4: =N4/SUM($D$4:$D$23) -> 0.062044338 | P4: =SUM($O$4:O4) -> 0.062044338 | Q4: =IF(P4<=0.8,"A",IF(P4<=0.95,"B","C")) -> A | S4: 1 | T4: =INDEX('Raw Data'!$AG$2:$AG$1001,MATCH($S4,'Raw Data'!$AL$2:$AL$1001,0)) -> NR-231210-0756 | U4: =INDEX('Raw Data'!$B$2:$B$1001,MATCH($S4,'Raw Data'!$AL$2:$AL$1001,0)) -> 45270 | V4: =INDEX('Raw Data'!$C$2:$C$1001,MATCH($S4,'Raw Data'!$AL$2:$AL$1001,0)) -> David | W4: =INDEX('Raw Data'!$D$2:$D$1001,MATCH($S4,'Raw Data'!$AL$2:$AL$1001,0)) -> North | X4: =INDEX('Raw Data'!$G$2:$G$1001,MATCH($S4,'Raw Data'!$AL$2:$AL$1001,0)) -> Food | Y4: =INDEX('Raw Data'!$M$2:$M$1001,MATCH($S4,'Raw Data'!$AL$2:$AL$1001,0)) -> Retail | Z4: =INDEX('Raw Data'!$E$2:$E$1001,MATCH($S4,'Raw Data'!$AL$2:$AL$1001,0)) -> 9989.04
A5: East-Bob | B5: East | C5: Bob | D5: =SUMIFS('Raw Data'!$E$2:$E$1001,'Raw Data'!$N$2:$N$1001,A5) -> 309876.11 | E5: =COUNTIFS('Raw Data'!$N$2:$N$1001,A5) -> 60 | F5: =IF(E5=0,0,D5/E5) -> 5164.6018 | G5: =IFERROR(SUMIFS('Raw Data'!$R$2:$R$1001,'Raw Data'!$N$2:$N$1001,A5)/SUMIFS('Raw Data'!$P$2:$P$1001,'Raw Data'!$N$2:$N$1001,A5),0) -> -0.10167661 | H5: =RANK(D5,$D$4:$D$23,0)+COUNTIF($D$4:D5,D5)-1 -> 2 | I5: =IF(D5>=PERCENTILE($D$4:$D$23,0.8),"High-Value",IF(D5>=PERCENTILE($D$4:$D$23,0.5),"Mid","Low")) -> High-Value | J5: =D5/SUM($D$4:$D$23) -> 0.061737345 | L5: 2 | M5: =INDEX($A$4:$A$23,MATCH(L5,$H$4:$H$23,0)) -> East-Bob | N5: =INDEX($D$4:$D$23,MATCH(L5,$H$4:$H$23,0)) -> 309876.11 | O5: =N5/SUM($D$4:$D$23) -> 0.061737345 | P5: =SUM($O$4:O5) -> 0.12378168 | Q5: =IF(P5<=0.8,"A",IF(P5<=0.95,"B","C")) -> A | S5: 2 | T5: =INDEX('Raw Data'!$AG$2:$AG$1001,MATCH($S5,'Raw Data'!$AL$2:$AL$1001,0)) -> NR-230821-0761 | U5: =INDEX('Raw Data'!$B$2:$B$1001,MATCH($S5,'Raw Data'!$AL$2:$AL$1001,0)) -> 45159 | V5: =INDEX('Raw Data'!$C$2:$C$1001,MATCH($S5,'Raw Data'!$AL$2:$AL$1001,0)) -> David | W5: =INDEX('Raw Data'!$D$2:$D$1001,MATCH($S5,'Raw Data'!$AL$2:$AL$1001,0)) -> North | X5: =INDEX('Raw Data'!$G$2:$G$1001,MATCH($S5,'Raw Data'!$AL$2:$AL$1001,0)) -> Furniture | Y5: =INDEX('Raw Data'!$M$2:$M$1001,MATCH($S5,'Raw Data'!$AL$2:$AL$1001,0)) -> Retail | Z5: =INDEX('Raw Data'!$E$2:$E$1001,MATCH($S5,'Raw Data'!$AL$2:$AL$1001,0)) -> 9976.52
A6: East-Charlie | B6: East | C6: Charlie | D6: =SUMIFS('Raw Data'!$E$2:$E$1001,'Raw Data'!$N$2:$N$1001,A6) -> 165172.94 | E6: =COUNTIFS('Raw Data'!$N$2:$N$1001,A6) -> 37 | F6: =IF(E6=0,0,D6/E6) -> 4464.1335 | G6: =IFERROR(SUMIFS('Raw Data'!$R$2:$R$1001,'Raw Data'!$N$2:$N$1001,A6)/SUMIFS('Raw Data'!$P$2:$P$1001,'Raw Data'!$N$2:$N$1001,A6),0) -> -0.082355996 | H6: =RANK(D6,$D$4:$D$23,0)+COUNTIF($D$4:D6,D6)-1 -> 19 | I6: =IF(D6>=PERCENTILE($D$4:$D$23,0.8),"High-Value",IF(D6>=PERCENTILE($D$4:$D$23,0.5),"Mid","Low")) -> Low | J6: =D6/SUM($D$4:$D$23) -> 0.032907793 | L6: 3 | M6: =INDEX($A$4:$A$23,MATCH(L6,$H$4:$H$23,0)) -> North-Eve | N6: =INDEX($D$4:$D$23,MATCH(L6,$H$4:$H$23,0)) -> 304172.2 | O6: =N6/SUM($D$4:$D$23) -> 0.060600942 | P6: =SUM($O$4:O6) -> 0.18438263 | Q6: =IF(P6<=0.8,"A",IF(P6<=0.95,"B","C")) -> A | S6: 3 | T6: =INDEX('Raw Data'!$AG$2:$AG$1001,MATCH($S6,'Raw Data'!$AL$2:$AL$1001,0)) -> NO-230824-0856 | U6: =INDEX('Raw Data'!$B$2:$B$1001,MATCH($S6,'Raw Data'!$AL$2:$AL$1001,0)) -> 45162 | V6: =INDEX('Raw Data'!$C$2:$C$1001,MATCH($S6,'Raw Data'!$AL$2:$AL$1001,0)) -> Alice | W6: =INDEX('Raw Data'!$D$2:$D$1001,MATCH($S6,'Raw Data'!$AL$2:$AL$1001,0)) -> North | X6: =INDEX('Raw Data'!$G$2:$G$1001,MATCH($S6,'Raw Data'!$AL$2:$AL$1001,0)) -> Clothing | Y6: =INDEX('Raw Data'!$M$2:$M$1001,MATCH($S6,'Raw Data'!$AL$2:$AL$1001,0)) -> Online | Z6: =INDEX('Raw Data'!$E$2:$E$1001,MATCH($S6,'Raw Data'!$AL$2:$AL$1001,0)) -> 9972.66
A7: East-David | B7: East | C7: David | D7: =SUMIFS('Raw Data'!$E$2:$E$1001,'Raw Data'!$N$2:$N$1001,A7) -> 284613.51 | E7: =COUNTIFS('Raw Data'!$N$2:$N$1001,A7) -> 59 | F7: =IF(E7=0,0,D7/E7) -> 4823.9578 | G7: =IFERROR(SUMIFS('Raw Data'!$R$2:$R$1001,'Raw Data'!$N$2:$N$1001,A7)/SUMIFS('Raw Data'!$P$2:$P$1001,'Raw Data'!$N$2:$N$1001,A7),0) -> -0.080190931 | H7: =RANK(D7,$D$4:$D$23,0)+COUNTIF($D$4:D7,D7)-1 -> 6 | I7: =IF(D7>=PERCENTILE($D$4:$D$23,0.8),"High-Value",IF(D7>=PERCENTILE($D$4:$D$23,0.5),"Mid","Low")) -> Mid | J7: =D7/SUM($D$4:$D$23) -> 0.056704218 | L7: 4 | M7: =INDEX($A$4:$A$23,MATCH(L7,$H$4:$H$23,0)) -> North-Charlie | N7: =INDEX($D$4:$D$23,MATCH(L7,$H$4:$H$23,0)) -> 299789.01 | O7: =N7/SUM($D$4:$D$23) -> 0.059727669 | P7: =SUM($O$4:O7) -> 0.24411029 | Q7: =IF(P7<=0.8,"A",IF(P7<=0.95,"B","C")) -> A | S7: 4 | T7: =INDEX('Raw Data'!$AG$2:$AG$1001,MATCH($S7,'Raw Data'!$AL$2:$AL$1001,0)) -> NR-230815-0655 | U7: =INDEX('Raw Data'!$B$2:$B$1001,MATCH($S7,'Raw Data'!$AL$2:$AL$1001,0)) -> 45153 | V7: =INDEX('Raw Data'!$C$2:$C$1001,MATCH($S7,'Raw Data'!$AL$2:$AL$1001,0)) -> Charlie | W7: =INDEX('Raw Data'!$D$2:$D$1001,MATCH($S7,'Raw Data'!$AL$2:$AL$1001,0)) -> North | X7: =INDEX('Raw Data'!$G$2:$G$1001,MATCH($S7,'Raw Data'!$AL$2:$AL$1001,0)) -> Clothing | Y7: =INDEX('Raw Data'!$M$2:$M$1001,MATCH($S7,'Raw Data'!$AL$2:$AL$1001,0)) -> Retail | Z7: =INDEX('Raw Data'!$E$2:$E$1001,MATCH($S7,'Raw Data'!$AL$2:$AL$1001,0)) -> 9972.11
A8: East-Eve | B8: East | C8: Eve | D8: =SUMIFS('Raw Data'!$E$2:$E$1001,'Raw Data'!$N$2:$N$1001,A8) -> 239340.9 | E8: =COUNTIFS('Raw Data'!$N$2:$N$1001,A8) -> 55 | F8: =IF(E8=0,0,D8/E8) -> 4351.6527 | G8: =IFERROR(SUMIFS('Raw Data'!$R$2:$R$1001,'Raw Data'!$N$2:$N$1001,A8)/SUMIFS('Raw Data'!$P$2:$P$1001,'Raw Data'!$N$2:$N$1001,A8),0) -> -0.07234197 | H8: =RANK(D8,$D$4:$D$23,0)+COUNTIF($D$4:D8,D8)-1 -> 14 | I8: =IF(D8>=PERCENTILE($D$4:$D$23,0.8),"High-Value",IF(D8>=PERCENTILE($D$4:$D$23,0.5),"Mid","Low")) -> Low | J8: =D8/SUM($D$4:$D$23) -> 0.04768445 | L8: 5 | M8: =INDEX($A$4:$A$23,MATCH(L8,$H$4:$H$23,0)) -> West-Bob | N8: =INDEX($D$4:$D$23,MATCH(L8,$H$4:$H$23,0)) -> 286449.28 | O8: =N8/SUM($D$4:$D$23) -> 0.057069963 | P8: =SUM($O$4:O8) -> 0.30118026 | Q8: =IF(P8<=0.8,"A",IF(P8<=0.95,"B","C")) -> A | S8: 5 | T8: =INDEX('Raw Data'!$AG$2:$AG$1001,MATCH($S8,'Raw Data'!$AL$2:$AL$1001,0)) -> SO-230423-0749 | U8: =INDEX('Raw Data'!$B$2:$B$1001,MATCH($S8,'Raw Data'!$AL$2:$AL$1001,0)) -> 45039 | V8: =INDEX('Raw Data'!$C$2:$C$1001,MATCH($S8,'Raw Data'!$AL$2:$AL$1001,0)) -> David | W8: =INDEX('Raw Data'!$D$2:$D$1001,MATCH($S8,'Raw Data'!$AL$2:$AL$1001,0)) -> South | X8: =INDEX('Raw Data'!$G$2:$G$1001,MATCH($S8,'Raw Data'!$AL$2:$AL$1001,0)) -> Furniture | Y8: =INDEX('Raw Data'!$M$2:$M$1001,MATCH($S8,'Raw Data'!$AL$2:$AL$1001,0)) -> Online | Z8: =INDEX('Raw Data'!$E$2:$E$1001,MATCH($S8,'Raw Data'!$AL$2:$AL$1001,0)) -> 9961.96
A9: North-Alice | B9: North | C9: Alice | D9: =SUMIFS('Raw Data'!$E$2:$E$1001,'Raw Data'!$N$2:$N$1001,A9) -> 249647.22 | E9: =COUNTIFS('Raw Data'!$N$2:$N$1001,A9) -> 48 | F9: =IF(E9=0,0,D9/E9) -> 5200.9838 | G9: =IFERROR(SUMIFS('Raw Data'!$R$2:$R$1001,'Raw Data'!$N$2:$N$1001,A9)/SUMIFS('Raw Data'!$P$2:$P$1001,'Raw Data'!$N$2:$N$1001,A9),0) -> -0.034112274 | H9: =RANK(D9,$D$4:$D$23,0)+COUNTIF($D$4:D9,D9)-1 -> 11 | I9: =IF(D9>=PERCENTILE($D$4:$D$23,0.8),"High-Value",IF(D9>=PERCENTILE($D$4:$D$23,0.5),"Mid","Low")) -> Low | J9: =D9/SUM($D$4:$D$23) -> 0.049737802 | L9: 6 | M9: =INDEX($A$4:$A$23,MATCH(L9,$H$4:$H$23,0)) -> East-David | N9: =INDEX($D$4:$D$23,MATCH(L9,$H$4:$H$23,0)) -> 284613.51 | O9: =N9/SUM($D$4:$D$23) -> 0.056704218 | P9: =SUM($O$4:O9) -> 0.35788447 | Q9: =IF(P9<=0.8,"A",IF(P9<=0.95,"B","C")) -> A | S9: 6 | T9: =INDEX('Raw Data'!$AG$2:$AG$1001,MATCH($S9,'Raw Data'!$AL$2:$AL$1001,0)) -> NO-230814-0797 | U9: =INDEX('Raw Data'!$B$2:$B$1001,MATCH($S9,'Raw Data'!$AL$2:$AL$1001,0)) -> 45152 | V9: =INDEX('Raw Data'!$C$2:$C$1001,MATCH($S9,'Raw Data'!$AL$2:$AL$1001,0)) -> Bob | W9: =INDEX('Raw Data'!$D$2:$D$1001,MATCH($S9,'Raw Data'!$AL$2:$AL$1001,0)) -> North | X9: =INDEX('Raw Data'!$G$2:$G$1001,MATCH($S9,'Raw Data'!$AL$2:$AL$1001,0)) -> Clothing | Y9: =INDEX('Raw Data'!$M$2:$M$1001,MATCH($S9,'Raw Data'!$AL$2:$AL$1001,0)) -> Online | Z9: =INDEX('Raw Data'!$E$2:$E$1001,MATCH($S9,'Raw Data'!$AL$2:$AL$1001,0)) -> 9956.75
A10: North-Bob | B10: North | C10: Bob | D10: =SUMIFS('Raw Data'!$E$2:$E$1001,'Raw Data'!$N$2:$N$1001,A10) -> 233464.81 | E10: =COUNTIFS('Raw Data'!$N$2:$N$1001,A10) -> 44 | F10: =IF(E10=0,0,D10/E10) -> 5306.0184 | G10: =IFERROR(SUMIFS('Raw Data'!$R$2:$R$1001,'Raw Data'!$N$2:$N$1001,A10)/SUMIFS('Raw Data'!$P$2:$P$1001,'Raw Data'!$N$2:$N$1001,A10),0) -> -0.074635448 | H10: =RANK(D10,$D$4:$D$23,0)+COUNTIF($D$4:D10,D10)-1 -> 15 | I10: =IF(D10>=PERCENTILE($D$4:$D$23,0.8),"High-Value",IF(D10>=PERCENTILE($D$4:$D$23,0.5),"Mid","Low")) -> Low | J10: =D10/SUM($D$4:$D$23) -> 0.046513742 | L10: 7 | M10: =INDEX($A$4:$A$23,MATCH(L10,$H$4:$H$23,0)) -> North-David | N10: =INDEX($D$4:$D$23,MATCH(L10,$H$4:$H$23,0)) -> 282539.27 | O10: =N10/SUM($D$4:$D$23) -> 0.056290962 | P10: =SUM($O$4:O10) -> 0.41417544 | Q10: =IF(P10<=0.8,"A",IF(P10<=0.95,"B","C")) -> A | S10: 7 | T10: =INDEX('Raw Data'!$AG$2:$AG$1001,MATCH($S10,'Raw Data'!$AL$2:$AL$1001,0)) -> EO-230414-0143 | U10: =INDEX('Raw Data'!$B$2:$B$1001,MATCH($S10,'Raw Data'!$AL$2:$AL$1001,0)) -> 45030 | V10: =INDEX('Raw Data'!$C$2:$C$1001,MATCH($S10,'Raw Data'!$AL$2:$AL$1001,0)) -> Alice | W10: =INDEX('Raw Data'!$D$2:$D$1001,MATCH($S10,'Raw Data'!$AL$2:$AL$1001,0)) -> East | X10: =INDEX('Raw Data'!$G$2:$G$1001,MATCH($S10,'Raw Data'!$AL$2:$AL$1001,0)) -> Food | Y10: =INDEX('Raw Data'!$M$2:$M$1001,MATCH($S10,'Raw Data'!$AL$2:$AL$1001,0)) -> Online | Z10: =INDEX('Raw Data'!$E$2:$E$1001,MATCH($S10,'Raw Data'!$AL$2:$AL$1001,0)) -> 9948.71
A11: North-Charlie | B11: North | C11: Charlie | D11: =SUMIFS('Raw Data'!$E$2:$E$1001,'Raw Data'!$N$2:$N$1001,A11) -> 299789.01 | E11: =COUNTIFS('Raw Data'!$N$2:$N$1001,A11) -> 55 | F11: =IF(E11=0,0,D11/E11) -> 5450.7093 | G11: =IFERROR(SUMIFS('Raw Data'!$R$2:$R$1001,'Raw Data'!$N$2:$N$1001,A11)/SUMIFS('Raw Data'!$P$2:$P$1001,'Raw Data'!$N$2:$N$1001,A11),0) -> -0.051989203 | H11: =RANK(D11,$D$4:$D$23,0)+COUNTIF($D$4:D11,D11)-1 -> 4 | I11: =IF(D11>=PERCENTILE($D$4:$D$23,0.8),"High-Value",IF(D11>=PERCENTILE($D$4:$D$23,0.5),"Mid","Low")) -> High-Value | J11: =D11/SUM($D$4:$D$23) -> 0.059727669 | L11: 8 | M11: =INDEX($A$4:$A$23,MATCH(L11,$H$4:$H$23,0)) -> West-David | N11: =INDEX($D$4:$D$23,MATCH(L11,$H$4:$H$23,0)) -> 263167.59 | O11: =N11/SUM($D$4:$D$23) -> 0.052431497 | P11: =SUM($O$4:O11) -> 0.46660693 | Q11: =IF(P11<=0.8,"A",IF(P11<=0.95,"B","C")) -> A | S11: 8 | T11: =INDEX('Raw Data'!$AG$2:$AG$1001,MATCH($S11,'Raw Data'!$AL$2:$AL$1001,0)) -> WR-231019-0190 | U11: =INDEX('Raw Data'!$B$2:$B$1001,MATCH($S11,'Raw Data'!$AL$2:$AL$1001,0)) -> 45218 | V11: =INDEX('Raw Data'!$C$2:$C$1001,MATCH($S11,'Raw Data'!$AL$2:$AL$1001,0)) -> Eve | W11: =INDEX('Raw Data'!$D$2:$D$1001,MATCH($S11,'Raw Data'!$AL$2:$AL$1001,0)) -> West | X11: =INDEX('Raw Data'!$G$2:$G$1001,MATCH($S11,'Raw Data'!$AL$2:$AL$1001,0)) -> Food | Y11: =INDEX('Raw Data'!$M$2:$M$1001,MATCH($S11,'Raw Data'!$AL$2:$AL$1001,0)) -> Retail | Z11: =INDEX('Raw Data'!$E$2:$E$1001,MATCH($S11,'Raw Data'!$AL$2:$AL$1001,0)) -> 9933.22
A12: North-David | B12: North | C12: David | D12: =SUMIFS('Raw Data'!$E$2:$E$1001,'Raw Data'!$N$2:$N$1001,A12) -> 282539.27 | E12: =COUNTIFS('Raw Data'!$N$2:$N$1001,A12) -> 56 | F12: =IF(E12=0,0,D12/E12) -> 5045.3441 | G12: =IFERROR(SUMIFS('Raw Data'!$R$2:$R$1001,'Raw Data'!$N$2:$N$1001,A12)/SUMIFS('Raw Data'!$P$2:$P$1001,'Raw Data'!$N$2:$N$1001,A12),0) -> -0.095243245 | H12: =RANK(D12,$D$4:$D$23,0)+COUNTIF($D$4:D12,D12)-1 -> 7 | I12: =IF(D12>=PERCENTILE($D$4:$D$23,0.8),"High-Value",IF(D12>=PERCENTILE($D$4:$D$23,0.5),"Mid","Low")) -> Mid | J12: =D12/SUM($D$4:$D$23) -> 0.056290962 | L12: 9 | M12: =INDEX($A$4:$A$23,MATCH(L12,$H$4:$H$23,0)) -> East-Alice | N12: =INDEX($D$4:$D$23,MATCH(L12,$H$4:$H$23,0)) -> 260789.47 | O12: =N12/SUM($D$4:$D$23) -> 0.051957699 | P12: =SUM($O$4:O12) -> 0.51856463 | Q12: =IF(P12<=0.8,"A",IF(P12<=0.95,"B","C")) -> A | S12: 9 | T12: =INDEX('Raw Data'!$AG$2:$AG$1001,MATCH($S12,'Raw Data'!$AL$2:$AL$1001,0)) -> SR-230922-0090 | U12: =INDEX('Raw Data'!$B$2:$B$1001,MATCH($S12,'Raw Data'!$AL$2:$AL$1001,0)) -> 45191 | V12: =INDEX('Raw Data'!$C$2:$C$1001,MATCH($S12,'Raw Data'!$AL$2:$AL$1001,0)) -> David | W12: =INDEX('Raw Data'!$D$2:$D$1001,MATCH($S12,'Raw Data'!$AL$2:$AL$1001,0)) -> South | X12: =INDEX('Raw Data'!$G$2:$G$1001,MATCH($S12,'Raw Data'!$AL$2:$AL$1001,0)) -> Electronics | Y12: =INDEX('Raw Data'!$M$2:$M$1001,MATCH($S12,'Raw Data'!$AL$2:$AL$1001,0)) -> Retail | Z12: =INDEX('Raw Data'!$E$2:$E$1001,MATCH($S12,'Raw Data'!$AL$2:$AL$1001,0)) -> 9914.15
A13: North-Eve | B13: North | C13: Eve | D13: =SUMIFS('Raw Data'!$E$2:$E$1001,'Raw Data'!$N$2:$N$1001,A13) -> 304172.2 | E13: =COUNTIFS('Raw Data'!$N$2:$N$1001,A13) -> 64 | F13: =IF(E13=0,0,D13/E13) -> 4752.6906 | G13: =IFERROR(SUMIFS('Raw Data'!$R$2:$R$1001,'Raw Data'!$N$2:$N$1001,A13)/SUMIFS('Raw Data'!$P$2:$P$1001,'Raw Data'!$N$2:$N$1001,A13),0) -> -0.044670885 | H13: =RANK(D13,$D$4:$D$23,0)+COUNTIF($D$4:D13,D13)-1 -> 3 | I13: =IF(D13>=PERCENTILE($D$4:$D$23,0.8),"High-Value",IF(D13>=PERCENTILE($D$4:$D$23,0.5),"Mid","Low")) -> High-Value | J13: =D13/SUM($D$4:$D$23) -> 0.060600942 | L13: 10 | M13: =INDEX($A$4:$A$23,MATCH(L13,$H$4:$H$23,0)) -> South-Bob | N13: =INDEX($D$4:$D$23,MATCH(L13,$H$4:$H$23,0)) -> 251200.43 | O13: =N13/SUM($D$4:$D$23) -> 0.050047252 | P13: =SUM($O$4:O13) -> 0.56861188 | Q13: =IF(P13<=0.8,"A",IF(P13<=0.95,"B","C")) -> A | S13: 10 | T13: =INDEX('Raw Data'!$AG$2:$AG$1001,MATCH($S13,'Raw Data'!$AL$2:$AL$1001,0)) -> NO-231012-0785 | U13: =INDEX('Raw Data'!$B$2:$B$1001,MATCH($S13,'Raw Data'!$AL$2:$AL$1001,0)) -> 45211 | V13: =INDEX('Raw Data'!$C$2:$C$1001,MATCH($S13,'Raw Data'!$AL$2:$AL$1001,0)) -> Charlie | W13: =INDEX('Raw Data'!$D$2:$D$1001,MATCH($S13,'Raw Data'!$AL$2:$AL$1001,0)) -> North | X13: =INDEX('Raw Data'!$G$2:$G$1001,MATCH($S13,'Raw Data'!$AL$2:$AL$1001,0)) -> Furniture | Y13: =INDEX('Raw Data'!$M$2:$M$1001,MATCH($S13,'Raw Data'!$AL$2:$AL$1001,0)) -> Online | Z13: =INDEX('Raw Data'!$E$2:$E$1001,MATCH($S13,'Raw Data'!$AL$2:$AL$1001,0)) -> 9907.72
A14: South-Alice | B14: South | C14: Alice | D14: =SUMIFS('Raw Data'!$E$2:$E$1001,'Raw Data'!$N$2:$N$1001,A14) -> 239414.54 | E14: =COUNTIFS('Raw Data'!$N$2:$N$1001,A14) -> 45 | F14: =IF(E14=0,0,D14/E14) -> 5320.3231 | G14: =IFERROR(SUMIFS('Raw Data'!$R$2:$R$1001,'Raw Data'!$N$2:$N$1001,A14)/SUMIFS('Raw Data'!$P$2:$P$1001,'Raw Data'!$N$2:$N$1001,A14),0) -> -0.07856639 | H14: =RANK(D14,$D$4:$D$23,0)+COUNTIF($D$4:D14,D14)-1 -> 13 | I14: =IF(D14>=PERCENTILE($D$4:$D$23,0.8),"High-Value",IF(D14>=PERCENTILE($D$4:$D$23,0.5),"Mid","Low")) -> Low | J14: =D14/SUM($D$4:$D$23) -> 0.047699121 | L14: 11 | M14: =INDEX($A$4:$A$23,MATCH(L14,$H$4:$H$23,0)) -> North-Alice | N14: =INDEX($D$4:$D$23,MATCH(L14,$H$4:$H$23,0)) -> 249647.22 | O14: =N14/SUM($D$4:$D$23) -> 0.049737802 | P14: =SUM($O$4:O14) -> 0.61834969 | Q14: =IF(P14<=0.8,"A",IF(P14<=0.95,"B","C")) -> A
A15: South-Bob | B15: South | C15: Bob | D15: =SUMIFS('Raw Data'!$E$2:$E$1001,'Raw Data'!$N$2:$N$1001,A15) -> 251200.43 | E15: =COUNTIFS('Raw Data'!$N$2:$N$1001,A15) -> 50 | F15: =IF(E15=0,0,D15/E15) -> 5024.0086 | G15: =IFERROR(SUMIFS('Raw Data'!$R$2:$R$1001,'Raw Data'!$N$2:$N$1001,A15)/SUMIFS('Raw Data'!$P$2:$P$1001,'Raw Data'!$N$2:$N$1001,A15),0) -> -0.036569273 | H15: =RANK(D15,$D$4:$D$23,0)+COUNTIF($D$4:D15,D15)-1 -> 10 | I15: =IF(D15>=PERCENTILE($D$4:$D$23,0.8),"High-Value",IF(D15>=PERCENTILE($D$4:$D$23,0.5),"Mid","Low")) -> Mid | J15: =D15/SUM($D$4:$D$23) -> 0.050047252 | L15: 12 | M15: =INDEX($A$4:$A$23,MATCH(L15,$H$4:$H$23,0)) -> West-Charlie | N15: =INDEX($D$4:$D$23,MATCH(L15,$H$4:$H$23,0)) -> 239708.85 | O15: =N15/SUM($D$4:$D$23) -> 0.047757757 | P15: =SUM($O$4:O15) -> 0.66610744 | Q15: =IF(P15<=0.8,"A",IF(P15<=0.95,"B","C")) -> A
A16: South-Charlie | B16: South | C16: Charlie | D16: =SUMIFS('Raw Data'!$E$2:$E$1001,'Raw Data'!$N$2:$N$1001,A16) -> 156140.68 | E16: =COUNTIFS('Raw Data'!$N$2:$N$1001,A16) -> 32 | F16: =IF(E16=0,0,D16/E16) -> 4879.3962 | G16: =IFERROR(SUMIFS('Raw Data'!$R$2:$R$1001,'Raw Data'!$N$2:$N$1001,A16)/SUMIFS('Raw Data'!$P$2:$P$1001,'Raw Data'!$N$2:$N$1001,A16),0) -> -0.05076461 | H16: =RANK(D16,$D$4:$D$23,0)+COUNTIF($D$4:D16,D16)-1 -> 20 | I16: =IF(D16>=PERCENTILE($D$4:$D$23,0.8),"High-Value",IF(D16>=PERCENTILE($D$4:$D$23,0.5),"Mid","Low")) -> Low | J16: =D16/SUM($D$4:$D$23) -> 0.031108274 | L16: 13 | M16: =INDEX($A$4:$A$23,MATCH(L16,$H$4:$H$23,0)) -> South-Alice | N16: =INDEX($D$4:$D$23,MATCH(L16,$H$4:$H$23,0)) -> 239414.54 | O16: =N16/SUM($D$4:$D$23) -> 0.047699121 | P16: =SUM($O$4:O16) -> 0.71380656 | Q16: =IF(P16<=0.8,"A",IF(P16<=0.95,"B","C")) -> A
A17: South-David | B17: South | C17: David | D17: =SUMIFS('Raw Data'!$E$2:$E$1001,'Raw Data'!$N$2:$N$1001,A17) -> 311416.99 | E17: =COUNTIFS('Raw Data'!$N$2:$N$1001,A17) -> 56 | F17: =IF(E17=0,0,D17/E17) -> 5561.0177 | G17: =IFERROR(SUMIFS('Raw Data'!$R$2:$R$1001,'Raw Data'!$N$2:$N$1001,A17)/SUMIFS('Raw Data'!$P$2:$P$1001,'Raw Data'!$N$2:$N$1001,A17),0) -> -0.070407378 | H17: =RANK(D17,$D$4:$D$23,0)+COUNTIF($D$4:D17,D17)-1 -> 1 | I17: =IF(D17>=PERCENTILE($D$4:$D$23,0.8),"High-Value",IF(D17>=PERCENTILE($D$4:$D$23,0.5),"Mid","Low")) -> High-Value | J17: =D17/SUM($D$4:$D$23) -> 0.062044338 | L17: 14 | M17: =INDEX($A$4:$A$23,MATCH(L17,$H$4:$H$23,0)) -> East-Eve | N17: =INDEX($D$4:$D$23,MATCH(L17,$H$4:$H$23,0)) -> 239340.9 | O17: =N17/SUM($D$4:$D$23) -> 0.04768445 | P17: =SUM($O$4:O17) -> 0.76149101 | Q17: =IF(P17<=0.8,"A",IF(P17<=0.95,"B","C")) -> A
A18: South-Eve | B18: South | C18: Eve | D18: =SUMIFS('Raw Data'!$E$2:$E$1001,'Raw Data'!$N$2:$N$1001,A18) -> 196078.22 | E18: =COUNTIFS('Raw Data'!$N$2:$N$1001,A18) -> 43 | F18: =IF(E18=0,0,D18/E18) -> 4559.9586 | G18: =IFERROR(SUMIFS('Raw Data'!$R$2:$R$1001,'Raw Data'!$N$2:$N$1001,A18)/SUMIFS('Raw Data'!$P$2:$P$1001,'Raw Data'!$N$2:$N$1001,A18),0) -> -0.067276551 | H18: =RANK(D18,$D$4:$D$23,0)+COUNTIF($D$4:D18,D18)-1 -> 18 | I18: =IF(D18>=PERCENTILE($D$4:$D$23,0.8),"High-Value",IF(D18>=PERCENTILE($D$4:$D$23,0.5),"Mid","Low")) -> Low | J18: =D18/SUM($D$4:$D$23) -> 0.039065124 | L18: 15 | M18: =INDEX($A$4:$A$23,MATCH(L18,$H$4:$H$23,0)) -> North-Bob | N18: =INDEX($D$4:$D$23,MATCH(L18,$H$4:$H$23,0)) -> 233464.81 | O18: =N18/SUM($D$4:$D$23) -> 0.046513742 | P18: =SUM($O$4:O18) -> 0.80800476 | Q18: =IF(P18<=0.8,"A",IF(P18<=0.95,"B","C")) -> B
A19: West-Alice | B19: West | C19: Alice | D19: =SUMIFS('Raw Data'!$E$2:$E$1001,'Raw Data'!$N$2:$N$1001,A19) -> 215690.54 | E19: =COUNTIFS('Raw Data'!$N$2:$N$1001,A19) -> 47 | F19: =IF(E19=0,0,D19/E19) -> 4589.1604 | G19: =IFERROR(SUMIFS('Raw Data'!$R$2:$R$1001,'Raw Data'!$N$2:$N$1001,A19)/SUMIFS('Raw Data'!$P$2:$P$1001,'Raw Data'!$N$2:$N$1001,A19),0) -> -0.031362681 | H19: =RANK(D19,$D$4:$D$23,0)+COUNTIF($D$4:D19,D19)-1 -> 17 | I19: =IF(D19>=PERCENTILE($D$4:$D$23,0.8),"High-Value",IF(D19>=PERCENTILE($D$4:$D$23,0.5),"Mid","Low")) -> Low | J19: =D19/SUM($D$4:$D$23) -> 0.042972533 | L19: 16 | M19: =INDEX($A$4:$A$23,MATCH(L19,$H$4:$H$23,0)) -> West-Eve | N19: =INDEX($D$4:$D$23,MATCH(L19,$H$4:$H$23,0)) -> 230592.67 | O19: =N19/SUM($D$4:$D$23) -> 0.045941519 | P19: =SUM($O$4:O19) -> 0.85394628 | Q19: =IF(P19<=0.8,"A",IF(P19<=0.95,"B","C")) -> B
A20: West-Bob | B20: West | C20: Bob | D20: =SUMIFS('Raw Data'!$E$2:$E$1001,'Raw Data'!$N$2:$N$1001,A20) -> 286449.28 | E20: =COUNTIFS('Raw Data'!$N$2:$N$1001,A20) -> 54 | F20: =IF(E20=0,0,D20/E20) -> 5304.6163 | G20: =IFERROR(SUMIFS('Raw Data'!$R$2:$R$1001,'Raw Data'!$N$2:$N$1001,A20)/SUMIFS('Raw Data'!$P$2:$P$1001,'Raw Data'!$N$2:$N$1001,A20),0) -> -0.046356405 | H20: =RANK(D20,$D$4:$D$23,0)+COUNTIF($D$4:D20,D20)-1 -> 5 | I20: =IF(D20>=PERCENTILE($D$4:$D$23,0.8),"High-Value",IF(D20>=PERCENTILE($D$4:$D$23,0.5),"Mid","Low")) -> Mid | J20: =D20/SUM($D$4:$D$23) -> 0.057069963 | L20: 17 | M20: =INDEX($A$4:$A$23,MATCH(L20,$H$4:$H$23,0)) -> West-Alice | N20: =INDEX($D$4:$D$23,MATCH(L20,$H$4:$H$23,0)) -> 215690.54 | O20: =N20/SUM($D$4:$D$23) -> 0.042972533 | P20: =SUM($O$4:O20) -> 0.89691881 | Q20: =IF(P20<=0.8,"A",IF(P20<=0.95,"B","C")) -> B
A21: West-Charlie | B21: West | C21: Charlie | D21: =SUMIFS('Raw Data'!$E$2:$E$1001,'Raw Data'!$N$2:$N$1001,A21) -> 239708.85 | E21: =COUNTIFS('Raw Data'!$N$2:$N$1001,A21) -> 45 | F21: =IF(E21=0,0,D21/E21) -> 5326.8633 | G21: =IFERROR(SUMIFS('Raw Data'!$R$2:$R$1001,'Raw Data'!$N$2:$N$1001,A21)/SUMIFS('Raw Data'!$P$2:$P$1001,'Raw Data'!$N$2:$N$1001,A21),0) -> -0.077525449 | H21: =RANK(D21,$D$4:$D$23,0)+COUNTIF($D$4:D21,D21)-1 -> 12 | I21: =IF(D21>=PERCENTILE($D$4:$D$23,0.8),"High-Value",IF(D21>=PERCENTILE($D$4:$D$23,0.5),"Mid","Low")) -> Low | J21: =D21/SUM($D$4:$D$23) -> 0.047757757 | L21: 18 | M21: =INDEX($A$4:$A$23,MATCH(L21,$H$4:$H$23,0)) -> South-Eve | N21: =INDEX($D$4:$D$23,MATCH(L21,$H$4:$H$23,0)) -> 196078.22 | O21: =N21/SUM($D$4:$D$23) -> 0.039065124 | P21: =SUM($O$4:O21) -> 0.93598393 | Q21: =IF(P21<=0.8,"A",IF(P21<=0.95,"B","C")) -> B
A22: West-David | B22: West | C22: David | D22: =SUMIFS('Raw Data'!$E$2:$E$1001,'Raw Data'!$N$2:$N$1001,A22) -> 263167.59 | E22: =COUNTIFS('Raw Data'!$N$2:$N$1001,A22) -> 51 | F22: =IF(E22=0,0,D22/E22) -> 5160.1488 | G22: =IFERROR(SUMIFS('Raw Data'!$R$2:$R$1001,'Raw Data'!$N$2:$N$1001,A22)/SUMIFS('Raw Data'!$P$2:$P$1001,'Raw Data'!$N$2:$N$1001,A22),0) -> -0.10824644 | H22: =RANK(D22,$D$4:$D$23,0)+COUNTIF($D$4:D22,D22)-1 -> 8 | I22: =IF(D22>=PERCENTILE($D$4:$D$23,0.8),"High-Value",IF(D22>=PERCENTILE($D$4:$D$23,0.5),"Mid","Low")) -> Mid | J22: =D22/SUM($D$4:$D$23) -> 0.052431497 | L22: 19 | M22: =INDEX($A$4:$A$23,MATCH(L22,$H$4:$H$23,0)) -> East-Charlie | N22: =INDEX($D$4:$D$23,MATCH(L22,$H$4:$H$23,0)) -> 165172.94 | O22: =N22/SUM($D$4:$D$23) -> 0.032907793 | P22: =SUM($O$4:O22) -> 0.96889173 | Q22: =IF(P22<=0.8,"A",IF(P22<=0.95,"B","C")) -> C
A23: West-Eve | B23: West | C23: Eve | D23: =SUMIFS('Raw Data'!$E$2:$E$1001,'Raw Data'!$N$2:$N$1001,A23) -> 230592.67 | E23: =COUNTIFS('Raw Data'!$N$2:$N$1001,A23) -> 47 | F23: =IF(E23=0,0,D23/E23) -> 4906.227 | G23: =IFERROR(SUMIFS('Raw Data'!$R$2:$R$1001,'Raw Data'!$N$2:$N$1001,A23)/SUMIFS('Raw Data'!$P$2:$P$1001,'Raw Data'!$N$2:$N$1001,A23),0) -> -0.091434793 | H23: =RANK(D23,$D$4:$D$23,0)+COUNTIF($D$4:D23,D23)-1 -> 16 | I23: =IF(D23>=PERCENTILE($D$4:$D$23,0.8),"High-Value",IF(D23>=PERCENTILE($D$4:$D$23,0.5),"Mid","Low")) -> Low | J23: =D23/SUM($D$4:$D$23) -> 0.045941519 | L23: 20 | M23: =INDEX($A$4:$A$23,MATCH(L23,$H$4:$H$23,0)) -> South-Charlie | N23: =INDEX($D$4:$D$23,MATCH(L23,$H$4:$H$23,0)) -> 156140.68 | O23: =N23/SUM($D$4:$D$23) -> 0.031108274 | P23: =SUM($O$4:O23) -> 1 | Q23: =IF(P23<=0.8,"A",IF(P23<=0.95,"B","C")) -> C
L25: ABC: A = first 80% of sales, B = next 15%, C = last 5%.

Sheet Product IDs
A1: Product IDs: frequency, repeats, and the two-list comparison
A2: Finding: a Product_ID is not tied to one category, so category-level analysis is used elsewhere. List A = IDs sold as Electronics, List B = IDs sold as Furniture; Matches = IDs sold in both.
A3: Product_ID | B3: Transactions | C3: Sales | D3: Categories_Sold | E3: Electronics_Orders | F3: Furniture_Orders | G3: Elec_Seq | H3: Furn_Seq | J3: # | K3: List A: sold as Electronics | L3: List B: sold as Furniture | M3: Matches (in both) | O3: Summary
